Workbook

Sheet How to use
A1: HIUSA QA test sheet
A3: What this is for
A4: 1. Each tab (SAO, Department Head, Admin & Adviser, SBO Officer, Student, General) lists test cases for one role.
A5: 2. Sign in with the account for that role, follow the Steps column, and compare what happens with the Expected result.
A6: 3. Set the Status for every case you run. Fill Tester, Date tested, and the device and browser you used.
A7: 4. If a case fails, set Severity, describe what you saw in Actual result / notes, and paste a screenshot link.
A8: 5. The Summary tab counts your entries by itself. Do not type in it.
A10: Test link
A11: Ask the host for the current link; it changes if the host restarts it.
A13: Test accounts
A14: Role | B14: School ID | C14: Notes
A15: SAO | B15: 990001 | C15: The only SAO account on the test copy. Runs the university side.
A16: Department Head | B16: 940001 to 940009 | C16: 940001 College of Computer Studies, 940002 Business Education, 940003 Teacher Education, 940004 Health Sciences, 940005 Engineering, 940006 Criminal Justice Education, 940007 Hospitality, Tourism and Customs Administration, 940008 Maritime Education, 940009 Nursing. One head per college; pick the college you were assigned.
A17: Admin (Organization Admin) | B17: 900001 to 900003, 920011 | C17: 900001 President, 900002 Vice President Internal, 900003 Secretary (all PSITS-CCS). 920011 is the President of JPIA-CBE.
A18: Adviser | B18: 990002, 990012, 990022, 990032, 990042 | C18: An Admin assigned by the SAO. 990002 PSITS-CCS, 990012 JPIA-CBE, 990022 FES-CTE, 990032 NSC-CHS, 990042 EIG-COE. Same menu as an Admin.
A19: SBO Officer | B19: 900004 to 900007 | C19: 900004 Treasurer, 900005 Auditor, 900006 Public Information Officer, 900007 Business Manager (all PSITS-CCS).
A20: Student | B20: 2100142 | C20: PSITS-CCS. Also 2100217, 2100389, 2200055, 2200134, 2200298, 2200451, 2300078, 2300163, 2300247, 2300312, 2400019, 2400067, 2400093. 2400118 belongs to FES-CTE and 2400133 to EIG-COE.
A21: Passwords: ask the host. Never share one account between two testers, because 5 wrong passwords lock it for 15 minutes.
A23: Status legend
A24: Not run | B24: Not tried yet. This is the starting value.
A25: Pass | B25: You ran every step and the result matched the Expected result.
A26: Fail | B26: You ran the steps and the result did not match. Set a Severity and describe it.
A27: Blocked | B27: You could not run it because something earlier is broken or missing (say what in the notes).
A28: N/A | B28: The case does not apply to you, for example a phone-only case on a laptop.
A30: How to report a bug
A31: Write these in the row of the failed case (Actual result / notes), or send them to the host:
A32: 1. Role and page (for example "Student, Store, Shop").
A33: 2. What you did, step by step.
A34: 3. What you expected.
A35: 4. What actually happened, with the exact message if there was one.
A36: 5. A screenshot, linked in the Bug screenshot link column.
A37: 6. Whether you used a phone or a laptop, and which browser.
A38: Severity: Critical = cannot continue or data is wrong or lost; Major = a feature does not work; Minor = works but is awkward or has a workaround; Cosmetic = looks wrong only.
A40: Run order
A41: Before anyone tests the Department Head registration cases, the SAO must set up a semester: sign in as the SAO (990001), open Academic years under Setup and records, add a semester that covers the whole test period, then choose Set as active on it. Adding it is not enough; it starts as upcoming. See docs/MEMBER_TESTING.md sections 3 and 4.
A42: Opening a semester hides the seeded events, tasks and election (they belong to no semester). So run the cases that use them first, then activate the semester and run the rest.
... A48: Blocked means you could not run the case because something it depends on failed or does not exist (write what in the notes). Cases that wait for a scheduled job run by the host and show nothing after waiting 3 minutes should be marked Blocked, with a note saying so.

Sheet Summary
A1: Summary (fills in by itself from the role tabs)
A3: Role | B3: Total | C3: Not run | D3: Pass | E3: Fail | F3: Blocked | G3: N/A | H3: Pass rate | I3: Progress | J3: Critical bugs | K3: Major bugs | L3: Minor bugs | M3: Cosmetic bugs
A4: SAO | B4: =COUNTA('SAO'!$A$2:$A$2000) -> 114 | C4: =B4-D4-E4-F4-G4 -> 114 | D4: =COUNTIF('SAO'!$M$2:$M$2000,"Pass") -> 0 | E4: =COUNTIF('SAO'!$M$2:$M$2000,"Fail") -> 0 | F4: =COUNTIF('SAO'!$M$2:$M$2000,"Blocked") -> 0 | G4: =COUNTIF('SAO'!$M$2:$M$2000,"N/A") -> 0 | H4: =IF(D4+E4=0,"",D4/(D4+E4)) | I4: =IF(B4=0,"",(B4-C4)/B4) -> 0 | J4: =COUNTIFS('SAO'!$M$2:$M$2000,"Fail",'SAO'!$N$2:$N$2000,"Critical") -> 0 | K4: =COUNTIFS('SAO'!$M$2:$M$2000,"Fail",'SAO'!$N$2:$N$2000,"Major") -> 0 | L4: =COUNTIFS('SAO'!$M$2:$M$2000,"Fail",'SAO'!$N$2:$N$2000,"Minor") -> 0 | M4: =COUNTIFS('SAO'!$M$2:$M$2000,"Fail",'SAO'!$N$2:$N$2000,"Cosmetic") -> 0
A5: Department Head | B5: =COUNTA('Department Head'!$A$2:$A$2000) -> 92 | C5: =B5-D5-E5-F5-G5 -> 92 | D5: =COUNTIF('Department Head'!$M$2:$M$2000,"Pass") -> 0 | E5: =COUNTIF('Department Head'!$M$2:$M$2000,"Fail") -> 0 | F5: =COUNTIF('Department Head'!$M$2:$M$2000,"Blocked") -> 0 | G5: =COUNTIF('Department Head'!$M$2:$M$2000,"N/A") -> 0 | H5: =IF(D5+E5=0,"",D5/(D5+E5)) | I5: =IF(B5=0,"",(B5-C5)/B5) -> 0 | J5: =COUNTIFS('Department Head'!$M$2:$M$2000,"Fail",'Department Head'!$N$2:$N$2000,"Critical") -> 0 | K5: =COUNTIFS('Department Head'!$M$2:$M$2000,"Fail",'Department Head'!$N$2:$N$2000,"Major") -> 0 | L5: =COUNTIFS('Department Head'!$M$2:$M$2000,"Fail",'Department Head'!$N$2:$N$2000,"Minor") -> 0 | M5: =COUNTIFS('Department Head'!$M$2:$M$2000,"Fail",'Department Head'!$N$2:$N$2000,"Cosmetic") -> 0
A6: Admin & Adviser | B6: =COUNTA('Admin & Adviser'!$A$2:$A$2000) -> 243 | C6: =B6-D6-E6-F6-G6 -> 243 | D6: =COUNTIF('Admin & Adviser'!$M$2:$M$2000,"Pass") -> 0 | E6: =COUNTIF('Admin & Adviser'!$M$2:$M$2000,"Fail") -> 0 | F6: =COUNTIF('Admin & Adviser'!$M$2:$M$2000,"Blocked") -> 0 | G6: =COUNTIF('Admin & Adviser'!$M$2:$M$2000,"N/A") -> 0 | H6: =IF(D6+E6=0,"",D6/(D6+E6)) | I6: =IF(B6=0,"",(B6-C6)/B6) -> 0 | J6: =COUNTIFS('Admin & Adviser'!$M$2:$M$2000,"Fail",'Admin & Adviser'!$N$2:$N$2000,"Critical") -> 0 | K6: =COUNTIFS('Admin & Adviser'!$M$2:$M$2000,"Fail",'Admin & Adviser'!$N$2:$N$2000,"Major") -> 0 | L6: =COUNTIFS('Admin & Adviser'!$M$2:$M$2000,"Fail",'Admin & Adviser'!$N$2:$N$2000,"Minor") -> 0 | M6: =COUNTIFS('Admin & Adviser'!$M$2:$M$2000,"Fail",'Admin & Adviser'!$N$2:$N$2000,"Cosmetic") -> 0
A7: SBO Officer | B7: =COUNTA('SBO Officer'!$A$2:$A$2000) -> 94 | C7: =B7-D7-E7-F7-G7 -> 94 | D7: =COUNTIF('SBO Officer'!$M$2:$M$2000,"Pass") -> 0 | E7: =COUNTIF('SBO Officer'!$M$2:$M$2000,"Fail") -> 0 | F7: =COUNTIF('SBO Officer'!$M$2:$M$2000,"Blocked") -> 0 | G7: =COUNTIF('SBO Officer'!$M$2:$M$2000,"N/A") -> 0 | H7: =IF(D7+E7=0,"",D7/(D7+E7)) | I7: =IF(B7=0,"",(B7-C7)/B7) -> 0 | J7: =COUNTIFS('SBO Officer'!$M$2:$M$2000,"Fail",'SBO Officer'!$N$2:$N$2000,"Critical") -> 0 | K7: =COUNTIFS('SBO Officer'!$M$2:$M$2000,"Fail",'SBO Officer'!$N$2:$N$2000,"Major") -> 0 | L7: =COUNTIFS('SBO Officer'!$M$2:$M$2000,"Fail",'SBO Officer'!$N$2:$N$2000,"Minor") -> 0 | M7: =COUNTIFS('SBO Officer'!$M$2:$M$2000,"Fail",'SBO Officer'!$N$2:$N$2000,"Cosmetic") -> 0
A8: Student | B8: =COUNTA('Student'!$A$2:$A$2000) -> 108 | C8: =B8-D8-E8-F8-G8 -> 108 | D8: =COUNTIF('Student'!$M$2:$M$2000,"Pass") -> 0 | E8: =COUNTIF('Student'!$M$2:$M$2000,"Fail") -> 0 | F8: =COUNTIF('Student'!$M$2:$M$2000,"Blocked") -> 0 | G8: =COUNTIF('Student'!$M$2:$M$2000,"N/A") -> 0 | H8: =IF(D8+E8=0,"",D8/(D8+E8)) | I8: =IF(B8=0,"",(B8-C8)/B8) -> 0 | J8: =COUNTIFS('Student'!$M$2:$M$2000,"Fail",'Student'!$N$2:$N$2000,"Critical") -> 0 | K8: =COUNTIFS('Student'!$M$2:$M$2000,"Fail",'Student'!$N$2:$N$2000,"Major") -> 0 | L8: =COUNTIFS('Student'!$M$2:$M$2000,"Fail",'Student'!$N$2:$N$2000,"Minor") -> 0 | M8: =COUNTIFS('Student'!$M$2:$M$2000,"Fail",'Student'!$N$2:$N$2000,"Cosmetic") -> 0
A9: General | B9: =COUNTA('General'!$A$2:$A$2000) -> 129 | C9: =B9-D9-E9-F9-G9 -> 129 | D9: =COUNTIF('General'!$M$2:$M$2000,"Pass") -> 0 | E9: =COUNTIF('General'!$M$2:$M$2000,"Fail") -> 0 | F9: =COUNTIF('General'!$M$2:$M$2000,"Blocked") -> 0 | G9: =COUNTIF('General'!$M$2:$M$2000,"N/A") -> 0 | H9: =IF(D9+E9=0,"",D9/(D9+E9)) | I9: =IF(B9=0,"",(B9-C9)/B9) -> 0 | J9: =COUNTIFS('General'!$M$2:$M$2000,"Fail",'General'!$N$2:$N$2000,"Critical") -> 0 | K9: =COUNTIFS('General'!$M$2:$M$2000,"Fail",'General'!$N$2:$N$2000,"Major") -> 0 | L9: =COUNTIFS('General'!$M$2:$M$2000,"Fail",'General'!$N$2:$N$2000,"Minor") -> 0 | M9: =COUNTIFS('General'!$M$2:$M$2000,"Fail",'General'!$N$2:$N$2000,"Cosmetic") -> 0
A10: All roles | B10: =SUM(B4:B9) -> 780 | C10: =SUM(C4:C9) -> 780 | D10: =SUM(D4:D9) -> 0 | E10: =SUM(E4:E9) -> 0 | F10: =SUM(F4:F9) -> 0 | G10: =SUM(G4:G9) -> 0 | H10: =IF(D10+E10=0,"",D10/(D10+E10)) | I10: =IF(B10=0,"",(B10-C10)/B10) -> 0 | J10: =SUM(J4:J9) -> 0 | K10: =SUM(K4:K9) -> 0 | L10: =SUM(L4:L9) -> 0 | M10: =SUM(M4:M9) -> 0
A12: Total = number of test cases on the tab. Not run = Total minus Pass, Fail, Blocked and N/A.
A13: Pass rate = Pass / (Pass + Fail). It only counts cases that were actually run to a result; Not run, Blocked and N/A are left out.
A14: Progress = (Total - Not run) / Total. It counts every case that has any status other than Not run.
A15: Bug columns count cases with Status = Fail and the matching Severity. A Fail with no Severity is in Fail but in none of the bug columns.
A16: Formulas read rows 2 to 2000 of each tab, so cases added below the last row are counted.
A18: By round
A19: Round | B19: Total | C19: Pass | D19: Fail | E19: Blocked
A20: Round 1 (before the SAO opens a semester) | B20: =COUNTIFS('SAO'!$G$2:$G$2000,$A20)+COUNTIFS('Department Head'!$G$2:$G$2000,$A20)+COUNTIFS('Admin & Adviser'!$G$2:$G$2000,$A20)+COUNTIFS('SBO Officer'!$G$2:$G$2000,$A20)+COUNTIFS('Student'!$G$2:$G$2000,$A20)+COUNTIFS('General'!$G$2:$G$2000,$A20) -> 24 | C20: =COUNTIFS('SAO'!$G$2:$G$2000,$A20,'SAO'!$M$2:$M$2000,"Pass")+COUNTIFS('Department Head'!$G$2:$G$2000,$A20,'Department Head'!$M$2:$M$2000,"Pass")+COUNTIFS('Admin & Adviser'!$G$2:$G$2000,$A20,'Admin & Adviser'!$M$2:$M$2000,"Pass")+COUNTIFS('SBO Officer'!$G$2:$G$2000,$A20,'SBO Officer'!$M$2:$M$2000,"Pass")+COUNTIFS('Student'!$G$2:$G$2000,$A20,'Student'!$M$2:$M$2000,"Pass")+COUNTIFS('General'!$G$2:$G$2000,$A20,'General'!$M$2:$M$2000,"Pass") -> 0 | D20: =COUNTIFS('SAO'!$G$2:$G$2000,$A20,'SAO'!$M$2:$M$2000,"Fail")+COUNTIFS('Department Head'!$G$2:$G$2000,$A20,'Department Head'!$M$2:$M$2000,"Fail")+COUNTIFS('Admin & Adviser'!$G$2:$G$2000,$A20,'Admin & Adviser'!$M$2:$M$2000,"Fail")+COUNTIFS('SBO Officer'!$G$2:$G$2000,$A20,'SBO Officer'!$M$2:$M$2000,"Fail")+COUNTIFS('Student'!$G$2:$G$2000,$A20,'Student'!$M$2:$M$2000,"Fail")+COUNTIFS('General'!$G$2:$G$2000,$A20,'General'!$M$2:$M$2000,"Fail") -> 0 | E20: =COUNTIFS('SAO'!$G$2:$G$2000,$A20,'SAO'!$M$2:$M$2000,"Blocked")+COUNTIFS('Department Head'!$G$2:$G$2000,$A20,'Department Head'!$M$2:$M$2000,"Blocked")+COUNTIFS('Admin & Adviser'!$G$2:$G$2000,$A20,'Admin & Adviser'!$M$2:$M$2000,"Blocked")+COUNTIFS('SBO Officer'!$G$2:$G$2000,$A20,'SBO Officer'!$M$2:$M$2000,"Blocked")+COUNTIFS('Student'!$G$2:$G$2000,$A20,'Student'!$M$2:$M$2000,"Blocked")+COUNTIFS('General'!$G$2:$G$2000,$A20,'General'!$M$2:$M$2000,"Blocked") -> 0
A21: Round 2 (after the SAO activates a semester) | B21: =COUNTIFS('SAO'!$G$2:$G$2000,$A21)+COUNTIFS('Department Head'!$G$2:$G$2000,$A21)+COUNTIFS('Admin & Adviser'!$G$2:$G$2000,$A21)+COUNTIFS('SBO Officer'!$G$2:$G$2000,$A21)+COUNTIFS('Student'!$G$2:$G$2000,$A21)+COUNTIFS('General'!$G$2:$G$2000,$A21) -> 25 | C21: =COUNTIFS('SAO'!$G$2:$G$2000,$A21,'SAO'!$M$2:$M$2000,"Pass")+COUNTIFS('Department Head'!$G$2:$G$2000,$A21,'Department Head'!$M$2:$M$2000,"Pass")+COUNTIFS('Admin & Adviser'!$G$2:$G$2000,$A21,'Admin & Adviser'!$M$2:$M$2000,"Pass")+COUNTIFS('SBO Officer'!$G$2:$G$2000,$A21,'SBO Officer'!$M$2:$M$2000,"Pass")+COUNTIFS('Student'!$G$2:$G$2000,$A21,'Student'!$M$2:$M$2000,"Pass")+COUNTIFS('General'!$G$2:$G$2000,$A21,'General'!$M$2:$M$2000,"Pass") -> 0 | D21: =COUNTIFS('SAO'!$G$2:$G$2000,$A21,'SAO'!$M$2:$M$2000,"Fail")+COUNTIFS('Department Head'!$G$2:$G$2000,$A21,'Department Head'!$M$2:$M$2000,"Fail")+COUNTIFS('Admin & Adviser'!$G$2:$G$2000,$A21,'Admin & Adviser'!$M$2:$M$2000,"Fail")+COUNTIFS('SBO Officer'!$G$2:$G$2000,$A21,'SBO Officer'!$M$2:$M$2000,"Fail")+COUNTIFS('Student'!$G$2:$G$2000,$A21,'Student'!$M$2:$M$2000,"Fail")+COUNTIFS('General'!$G$2:$G$2000,$A21,'General'!$M$2:$M$2000,"Fail") -> 0 | E21: =COUNTIFS('SAO'!$G$2:$G$2000,$A21,'SAO'!$M$2:$M$2000,"Blocked")+COUNTIFS('Department Head'!$G$2:$G$2000,$A21,'Department Head'!$M$2:$M$2000,"Blocked")+COUNTIFS('Admin & Adviser'!$G$2:$G$2000,$A21,'Admin & Adviser'!$M$2:$M$2000,"Blocked")+COUNTIFS('SBO Officer'!$G$2:$G$2000,$A21,'SBO Officer'!$M$2:$M$2000,"Blocked")+COUNTIFS('Student'!$G$2:$G$2000,$A21,'Student'!$M$2:$M$2000,"Blocked")+COUNTIFS('General'!$G$2:$G$2000,$A21,'General'!$M$2:$M$2000,"Blocked") -> 0
A22: Any time | B22: =COUNTIFS('SAO'!$G$2:$G$2000,$A22)+COUNTIFS('Department Head'!$G$2:$G$2000,$A22)+COUNTIFS('Admin & Adviser'!$G$2:$G$2000,$A22)+COUNTIFS('SBO Officer'!$G$2:$G$2000,$A22)+COUNTIFS('Student'!$G$2:$G$2000,$A22)+COUNTIFS('General'!$G$2:$G$2000,$A22) -> 731 | C22: =COUNTIFS('SAO'!$G$2:$G$2000,$A22,'SAO'!$M$2:$M$2000,"Pass")+COUNTIFS('Department Head'!$G$2:$G$2000,$A22,'Department Head'!$M$2:$M$2000,"Pass")+COUNTIFS('Admin & Adviser'!$G$2:$G$2000,$A22,'Admin & Adviser'!$M$2:$M$2000,"Pass")+COUNTIFS('SBO Officer'!$G$2:$G$2000,$A22,'SBO Officer'!$M$2:$M$2000,"Pass")+COUNTIFS('Student'!$G$2:$G$2000,$A22,'Student'!$M$2:$M$2000,"Pass")+COUNTIFS('General'!$G$2:$G$2000,$A22,'General'!$M$2:$M$2000,"Pass") -> 0 | D22: =COUNTIFS('SAO'!$G$2:$G$2000,$A22,'SAO'!$M$2:$M$2000,"Fail")+COUNTIFS('Department Head'!$G$2:$G$2000,$A22,'Department Head'!$M$2:$M$2000,"Fail")+COUNTIFS('Admin & Adviser'!$G$2:$G$2000,$A22,'Admin & Adviser'!$M$2:$M$2000,"Fail")+COUNTIFS('SBO Officer'!$G$2:$G$2000,$A22,'SBO Officer'!$M$2:$M$2000,"Fail")+COUNTIFS('Student'!$G$2:$G$2000,$A22,'Student'!$M$2:$M$2000,"Fail")+COUNTIFS('General'!$G$2:$G$2000,$A22,'General'!$M$2:$M$2000,"Fail") -> 0 | E22: =COUNTIFS('SAO'!$G$2:$G$2000,$A22,'SAO'!$M$2:$M$2000,"Blocked")+COUNTIFS('Department Head'!$G$2:$G$2000,$A22,'Department Head'!$M$2:$M$2000,"Blocked")+COUNTIFS('Admin & Adviser'!$G$2:$G$2000,$A22,'Admin & Adviser'!$M$2:$M$2000,"Blocked")+COUNTIFS('SBO Officer'!$G$2:$G$2000,$A22,'SBO Officer'!$M$2:$M$2000,"Blocked")+COUNTIFS('Student'!$G$2:$G$2000,$A22,'Student'!$M$2:$M$2000,"Blocked")+COUNTIFS('General'!$G$2:$G$2000,$A22,'General'!$M$2:$M$2000,"Blocked") -> 0
A23: Counts cases by the Round column on each role tab. Cases with no round set count under Any time.

Sheet SAO
A1: ID | B1: Module | C1: Test case | D1: Type | E1: Priority | F1: Device | G1: Round | H1: Depends on | I1: Preconditions | J1: Steps | K1: Expected result | L1: Author note (unconfirmed) | M1: Status | N1: Severity | O1: Tester | P1: Date tested | Q1: Device and browser used | R1: Actual result / notes | S1: Bug screenshot link
A2: SAO-001 | B2: Sign in and menu | C2: SAO signs in and reaches the SAO Dashboard | D2: Functional | E2: High | F2: Any | G2: Any time | I2: SAO account 990001 exists. The SAO password is given to you separately. You are signed out. | J2: 1. Open the HIUSA sign in page. 2. Type 990001 in School ID. 3. Type the SAO password in Password. 4. Select Sign in. 5. Look at the page that opens and at the left menu. | K2: You land on the SAO Dashboard (the address ends with /dashboard/super-admin). The left menu shows Dashboard, then the groups Organizations, Reviews, Updates and Setup and records, and Profile and Study objectives at the bottom. | L2: VERIFY: if a Change password screen appears first, set a new password and tell the demo owner, then continue. | M2: Not run
A3: SAO-002 | B3: Sign in and menu | C3: Sign in with a wrong password is refused | D3: Negative | E3: Medium | F3: Any | G3: Any time | I3: SAO account 990001 exists. You are signed out. | J3: 1. Open the HIUSA sign in page. 2. Type 990001 in School ID. 3. Type a wrong password in Password. 4. Select Sign in. 5. Read the message on the screen. | K3: You stay on the sign in page and a red message says the sign in failed. No Dashboard opens. Do this only once or twice: five wrong passwords lock the account for 15 minutes for everyone who shares it. | L3: VERIFY: the exact wording of the message. | M3: Not run
A4: SAO-003 | B4: Sign in and menu | C4: The SAO menu shows the right groups and pages and nothing from other roles | D4: Usability | E4: High | F4: Laptop | G4: Any time | I4: Signed in as SAO 990001. | J4: 1. Look at the left menu from top to bottom. 2. Select the group name Organizations and read the items under it. 3. Select the group name Reviews and read the items under it. 4. Select the group name Updates and read the items under it. 5. Select the group name Setup and records and read the items under it. 6. Look for any menu item named Approvals, Finance, Events, Voting or Store. | K4: The menu reads: Dashboard; Organizations (Agency overview, Registrations and organizations, Administrators, Colleges); Reviews (Compliance, Venues, Grievances, Clearances); Updates (University announcements, Notifications); Setup and records (Academic years, Audit trail); then Profile and Study objectives. Selecting a group opens its first page. The page you are on is highlighted. There is no Approvals, Finance, Events, Voting or Store item. | M4: Not run
A5: SAO-004 | B5: Sign in and menu | C5: On a phone the menu opens from the Open menu button | D5: Usability | E5: Medium | F5: Phone | G5: Any time | I5: Signed in as SAO 990001. Use a phone or a browser window narrower than 768 pixels. | J5: 1. Look at the top left of the screen for the Open menu button and select it. 2. Select the group Reviews. 3. Select Grievances. 4. Read the page title. 5. Open the menu again and select Dashboard. | K5: The menu slides in over the page. Choosing Grievances opens the Grievances page with its title. Choosing Dashboard returns to the Dashboard. The page does not scroll sideways. | L5: VERIFY: the menu closes by itself after you choose a page. | M5: Not run
A6: SAO-005 | B6: Sign in and menu | C6: Log out asks for confirmation and ends the session | D6: Functional | E6: Medium | F6: Any | G6: Any time | I6: Signed in as SAO 990001. | J6: 1. Select your name button at the top right (Account menu). 2. Select Logout. 3. Read the Log Out box, then select Cancel. 4. Select Account menu and Logout again. 5. Select Log Out in the box. 6. Press the browser Back button. | K6: The box titled Log Out says "You will need to sign in again to access your dashboard." Cancel keeps you signed in. Log Out takes you to the sign in page. Pressing Back does not show SAO data; you are asked to sign in. | L6: VERIFY: what Back shows. | M6: Not run
A7: SAO-006 | B7: Access control | C7: The SAO is sent home when it opens pages that belong to other roles | D7: Access | E7: High | F7: Laptop | G7: Any time | I7: Signed in as SAO 990001. | J7: 1. Click the address bar and replace the end of the address with /dashboard/admin, then press Enter. 2. Note which page opens. 3. Replace the address end with /dashboard/department-head/approvals and press Enter. 4. Replace the address end with /dashboard/finance/budget-allocation and press Enter. 5. Replace the address end with /dashboard/events/manage-events and press Enter. | K7: Every time the SAO is sent back to the SAO Dashboard. No page of another role is shown and no error page appears. | M7: Not run
A8: SAO-007 | B8: Access control | C8: Old SAO addresses forward to the Compliance tabs | D8: Functional | E8: Low | F8: Laptop | G8: Any time | I8: Signed in as SAO 990001. | J8: 1. Replace the address end with /dashboard/super-admin/approvals and press Enter. 2. Note the page and the selected tab. 3. Replace the address end with /dashboard/super-admin/financial-reports and press Enter. 4. Replace the address end with /dashboard/super-admin/event-requirements and press Enter. 5. Note the page and the selected tab. | K8: The first two addresses open Reviews > Compliance with the Financial reports tab selected (address ends with ?tab=financial). The third opens Compliance with the Event requirements tab selected (?tab=events). | M8: Not run
A9: SAO-008 | B9: Access control | C9: A visitor who is not signed in cannot open SAO pages | D9: Access | E9: High | F9: Any | G9: Any time | I9: You are signed out (log out first if needed). | J9: 1. Open the HIUSA address followed by /dashboard/super-admin. 2. Note which page opens. 3. Open the address followed by /dashboard/super-admin/admins. 4. Note which page opens. | K9: Both addresses show the sign in page. No SAO data is visible. | M9: Not run
A10: SAO-009 | B10: Access control | C10: Admin, Department Head and Student cannot open SAO pages | D10: Access | E10: High | F10: Laptop | G10: Any time | I10: Accounts: Admin 900001, Department Head 940001, Student 2100142. Passwords are given separately. | J10: 1. Sign in as Admin 900001. 2. Replace the address end with /dashboard/super-admin/admins and press Enter, then note the page. 3. Log out. Sign in as Department Head 940001. 4. Replace the address end with /dashboard/super-admin/organizations and press Enter, then note the page. 5. Log out. Sign in as Student 2100142. 6. Replace the address end with /dashboard/super-admin/audit-logs and press Enter, then note the page. | K10: Each person is sent back to their own home page (Admin dashboard, Department Head dashboard, Student dashboard). None of them sees an SAO page or SAO data. | M10: Not run
A11: SAO-010 | B11: Access control | C11: The SAO has no way to create an organization or a college | D11: Negative | E11: High | F11: Laptop | G11: Any time | I11: Signed in as SAO 990001. The server also answers "405 Method Not Allowed" to any request that tries to create one; automated tests pin that. | J11: 1. Open Organizations > Registrations and organizations and look at all four tabs for a New, Create, Add or Register button. 2. Open Organizations > Agency overview and look for the same buttons. 3. Open Organizations > Colleges and look for a New, Add, Create, Edit or Delete college button. 4. Count the college cards. 5. Read the buttons on one college card. | K11: There is no button to create an organization or a college anywhere. Organizations only offer Review, Open, Provision administrator, Restore and the actions menu (Edit organization, Add existing user, Manage user profiles, Archive organization). A college card only offers Manage, Assign Department Head, View organizations and Upload logo. A fresh seed shows 5 college cards. Department Heads register organizations. | M11: Not run
A12: SAO-011 | B12: Dashboard | C12: The Dashboard Review inbox lists what waits for the SAO | D12: Functional | E12: High | F12: Any | G12: Any time | I12: Signed in as SAO 990001. At least one registration or compliance submission is waiting (a Department Head 940001 has registered an organization, see Academic years first: A semester must be active first (Setup and records > Academic years, Set as active).). | J12: 1. Open Dashboard from the menu. 2. Find the card titled Review inbox. 3. Read each line and its number. 4. Select the line Registrations awaiting review. 5. Read the page that opens. | K12: Review inbox lists the queues that have work, for example Registrations awaiting review, Compliance submissions awaiting review, Financial reports to approve, Event files to approve and Venue bookings awaiting review, each with a count and a link. Registrations awaiting review opens Organizations > Registrations and organizations on the Pending review tab. | L12: VERIFY: whether a queue with zero items is hidden or shown as 0. | M12: Not run
A13: SAO-012 | B13: Dashboard | C13: The University operations numbers and the Organization filter agree with the real data | D13: Functional | E13: Medium | F13: Any | G13: Any time | I13: Signed in as SAO 990001. | J13: 1. Open Dashboard and find the card University operations. 2. Read the five numbers: Registered organizations, Active organizations, Inactive organizations, Financial reports to review, Unread Notifications. 3. Open Organizations > Agency overview and compare the Organizations and Pending reviews tiles. 4. Return to Dashboard and open the Organization filter at the top right. 5. Choose one organization from the list. 6. Read the numbers again, then choose All organizations. | K13: The numbers match the Agency overview. Filter options read "All organizations" and then "ACRONYM: Name" for each organization. After choosing one organization the numbers describe only that organization (Registered organizations shows 1). Choosing All organizations restores the totals. | M13: Not run
A14: SAO-013 | B14: Dashboard | C14: The SAO actions panel and Recent notifications lead to the right pages | D14: Functional | E14: Medium | F14: Any | G14: Any time | I14: Signed in as SAO 990001. | J14: 1. On the Dashboard find the panel SAO actions. 2. Select Registrations and organizations, read the page, then go back. 3. Do the same for Administrators, Colleges and Department Heads, Compliance and financial reports, University announcements and Notifications. 4. Scroll to Recent notifications and read it. 5. Select View all. | K14: The six links open Registrations and organizations, Administrators, Colleges, Compliance, University announcements and Notifications. Recent notifications shows titles and messages, or the sentence "No new notifications. Organization notices will appear here when they need your attention." View all opens the Notifications page. | M14: Not run
A15: SAO-014 | B15: Organizations > Agency overview | C15: The four tiles show totals and open the matching lists | D15: Functional | E15: High | F15: Any | G15: Any time | I15: Signed in as SAO 990001. | J15: 1. Open Organizations > Agency overview. 2. Read the tiles: Pending reviews, Organizations, Colleges, Archived. 3. Select Pending reviews, read the page, go back. 4. Select Organizations, read the page, go back. 5. Select Colleges, read the page, go back. 6. Select Archived and read the page. | K15: Pending reviews opens Registrations and organizations on the Pending review tab. Organizations opens the Active tab. Colleges opens the Colleges page. Archived opens the Archived tab. The numbers on the tiles match the tab counts. | M15: Not run
A16: SAO-015 | B16: Organizations > Agency overview | C16: Colleges with work to do come first and each college summarises its organizations | D16: Functional | E16: High | F16: Laptop | G16: Any time | I16: Signed in as SAO 990001. A semester must be active first (Setup and records > Academic years, Set as active). Department Head 940001 has registered a new organization that is still Pending review. | J16: 1. Open Organizations > Agency overview. 2. Read the summary line of each college header. 3. Check which college is listed first. 4. Select the arrow button on a college header to close it, then open it again. 5. Find the pending organization inside its college. | K16: Each college header reads like "1 organization · 1 pending · 0 active · 0 returned · 0 archived" (plus "n awaiting administrator" when an approved organization has no administrator). Colleges that need review are listed first and start open; quiet colleges come later. Inside a college the pending registration sits above organizations with "Nothing waiting". The arrow button opens and closes the list. | M16: Not run
A17: SAO-016 | B17: Organizations > Agency overview | C17: Each organization row offers only the actions that fit its status | D17: Functional | E17: High | F17: Any | G17: Any time | I17: Signed in as SAO 990001. One Pending, one Active organization with no administrator, and one Archived organization exist (use the registration journey to create them). | J17: 1. Open Organizations > Agency overview and find a Pending row. 2. Select Review on it, read the drawer, then close it. 3. Find an Active row with no administrator and select Provision administrator. 4. Go back and select Open on any row. 5. Find an Archived row and read its badge. | K17: Review appears only on Pending rows and opens the Review registration drawer. Provision administrator appears only on Active rows with no administrator and opens the Create administrator form for that organization. Open appears on every row and shows the Organization overview. The column Needs attention reads "Nothing waiting" or for example "1 approval, 2 documents". Archived rows show the badge "Archived, read only". | M17: Not run
A18: SAO-017 | B18: Organizations > Registrations and organizations | C18: The four tabs show counts and open on the right default | D18: Functional | E18: High | F18: Any | G18: Any time | I18: Signed in as SAO 990001. | J18: 1. Open Organizations > Registrations and organizations. 2. Read the four tab names and the number in brackets on each. 3. Select each tab in turn. 4. Read one card: name, code, college, status badge, members and admins. 5. Look at the address bar after each tab. | K18: Tabs read Pending review (n), Active (n), Returned (n) and Archived (n). The page opens on the first tab that has items in the order Pending, Returned, Active, Archived. The address shows ?status=pending, active, returned or archived. Cards are grouped under a college heading. A card shows the name, "ACRONYM · College", a status badge, and "N members · N admins". Pending cards also show "Submitted <date>". | M18: Not run
A19: SAO-018 | B19: Organizations > Registrations and organizations | C19: Search narrows the list and each tab has its own empty message | D19: Functional | E19: Medium | F19: Any | G19: Any time | I19: Signed in as SAO 990001. | J19: 1. On the Active tab type PSITS in Search organizations. 2. Clear it and type the name of a college, for example Business. 3. Clear it and type zzzz. 4. Read the empty message, then clear the search. 5. Open a tab that has no items (Pending review, Returned or Archived) and read its message. | K19: The placeholder reads "Name, code, or college". After a short pause the list shows only matching organizations (name, code or college). Searching zzzz shows "No active student organizations match this view." with "Try a different search term." Empty tabs say: Pending "No organizations are waiting for review."; Returned "No organizations are returned to their Department Head."; Archived "No archived organizations." each with a short hint line. | M19: Not run
A20: SAO-019 | B20: Organizations > Registrations and organizations | C20: The Review registration drawer shows the registration and its ten documents | D20: Functional | E20: High | F20: Any | G20: Any time | I20: Signed in as SAO 990001. A semester must be active first (Setup and records > Academic years, Set as active). Department Head 940001 has registered an organization with all ten files. | J20: 1. Open the Pending review tab. 2. Select Review on the new organization. 3. Read the drawer titled Review registration. 4. Scroll to Registration documents. 5. Select Open on the first document. | K20: The drawer shows the registration steps, Organization (name and code), College, Description, Submitted date and Submitted by. Registration documents lists 10 files, each with an Open button; Open shows the PDF in a new tab. The footer has Return and Approve, and a box Remarks (required to return). Approve stays greyed out while the details load. | M20: Not run
A21: SAO-020 | B21: Organizations > Registrations and organizations | C21: Return without remarks is refused | D21: Validation | E21: High | F21: Any | G21: Any time | I21: Signed in as SAO 990001. A Pending registration exists. | J21: 1. Open Review on a pending organization. 2. Leave Remarks empty. 3. Select Return. 4. Read the message under the Remarks box. 5. Close the drawer and look at the organization. | K21: The message "Add remarks explaining what the Department Head needs to fix." appears under Remarks and nothing is saved. The organization is still in Pending review. | M21: Not run
A22: SAO-021 | B22: Organizations > Registrations and organizations | C22: Return a registration with remarks and the Department Head sees it | D22: Functional | E22: High | F22: Any | G22: Any time | I22: Signed in as SAO 990001. A Pending registration from Department Head 940001 exists. | J22: 1. Open Review on the pending organization. 2. Type "Missing charter signature" in Remarks. 3. Select Return and read the green message. 4. Open the Returned tab and read the card. 5. Log out and sign in as Department Head 940001. 6. Open Organizations and find the row. | K22: The green message reads "<Organization name> returned to its Department Head." The drawer closes and the Pending count goes down by one. On the Returned tab the card shows "Returned with remarks" and your text. The Department Head sees the row as Returned with the SAO remarks and the button Edit and resubmit. | M22: Not run
A23: SAO-022 | B23: Organizations > Registrations and organizations | C23: Approve a registration and move on to give it an administrator | D23: Functional | E23: High | F23: Any | G23: Any time | I23: Signed in as SAO 990001. A Pending registration exists. | J23: 1. Open Review on the pending organization. 2. Select Approve and read the green message. 3. Read the next step shown in the drawer. 4. Select Provision administrator. 5. Read the Create administrator form. 6. Open the Active tab and find the organization. | K23: The message reads "<Organization name> approved and activated." The drawer stays open and says "Provision an administrator" with the text that the organization cannot sign in until it has one. Provision administrator opens Organizations > Administrators with the Create administrator form and the organization locked. On the Active tab the card shows Active and "0 admins". The Pending count drops by one. | M23: Not run
A24: SAO-023 | B24: Organizations > Registrations and organizations | C24: A registration that was already decided cannot be decided again | D24: Negative | E24: Medium | F24: Laptop | G24: Any time | I24: Signed in as SAO 990001. Two browser windows. A Pending registration exists. | J24: 1. In window A and window B, open Review on the same pending organization. 2. In window A select Approve. 3. In window B type some remarks and select Return (or select Approve). 4. Read the red message in window B. 5. Look at the Pending review tab in window B. | K24: Window B shows the red message "Only a pending registration can be reviewed." The drawer closes and the lists refresh. The organization stays Active; the second decision is not applied. | M24: Not run
A25: SAO-024 | B25: Organizations > Registrations and organizations | C25: Edit an active organization | D25: Functional | E25: High | F25: Any | G25: Any time | I25: Signed in as SAO 990001. Use an organization that is safe to change (not PSITS-CCS), for example one made in the registration journey. | J25: 1. Open the Active tab and find the organization card. 2. Select the actions menu (Organization actions) and choose Edit organization. 3. Change the Description and pick a new Organization color. 4. Select Save organization. 5. Read the green message and the card. | K25: The dialog Edit organization has Organization name, Organization code, Main organization, College (read only), Organization color, Organization logo (optional) and Description. After saving, "Organization updated." appears and the card shows the new description and colour stripe. | M25: Not run
A26: SAO-025 | B26: Organizations > Registrations and organizations | C26: Edit organization refuses empty and duplicate values | D26: Validation | E26: Medium | F26: Any | G26: Any time | I26: Signed in as SAO 990001. At least two active organizations exist. | J26: 1. Open Edit organization on an active organization. 2. Clear Organization name and select Save organization. 3. Type the name back. Change Organization code to the code of another organization. 4. Select Save organization and read the red message. 5. Set Organization name to the exact name of another organization and save again. 6. Cancel and look at the card. | K26: An empty name is stopped by the browser ("Please fill out this field") and nothing is sent. A duplicate code or name shows a red message such as "The acronym has already been taken." or "The name has already been taken." and the dialog stays open. After Cancel the card is unchanged. | L26: VERIFY: exact wording of the duplicate messages. | M26: Not run
A27: SAO-026 | B27: Organizations > Registrations and organizations | C27: Add an existing user to an organization and manage its user profiles | D27: Functional | E27: Medium | F27: Laptop | G27: Any time | I27: Signed in as SAO 990001. A user from the same college who belongs to another organization exists (if none, only the empty result can be tested). | J27: 1. On the Active tab open the actions menu of an organization and choose Add existing user. 2. Read the note under the organization name and type a School ID in Search existing users. 3. Choose the user, pick a Role in destination organization, and select Add user. 4. Open the actions menu again and choose Manage user profiles. 5. Search for a School ID. Select Delete profile on a throwaway profile only, then read the confirmation box and cancel. | K27: The note reads "College: <name>. Only eligible users from this college who are not already members are listed." With no match it says "No eligible users found in this college." Roles offered: Student, SBO Officer, Department Head, Admin. A successful add shows "User added to the organization." Manage user profiles lists "Name · School ID", "Organization · role · status" and "Primary profile" or "Additional profile". Delete profile asks you to type the School ID to confirm; a profile that cannot be removed shows a reason and its button is greyed. With no match: "No profiles found in the organizations you manage." | M27: Not run
A28: SAO-027 | B28: Organizations > Registrations and organizations | C28: Archive an active organization | D28: Functional | E28: High | F28: Any | G28: Any time | I28: Signed in as SAO 990001. Use a throwaway organization (not PSITS-CCS), because its members cannot sign in while it is archived. | J28: 1. On the Active tab open the actions menu of the throwaway organization. 2. Choose Archive organization. 3. Read the dialog and type a short Reason (optional). 4. Select Archive organization. 5. Read the green message. 6. Open the Archived tab and read the note at the top. | K28: The dialog says "<Name> becomes read-only and its members can no longer sign in. You can restore it later." After confirming, "<Name> archived." appears. The organization leaves the Active tab and shows on the Archived tab with the note "Archived organizations are read-only. Restore to make changes." and the badge "Archived, read only". | M28: Not run
A29: SAO-028 | B29: Organizations > Registrations and organizations | C29: An archived organization is read only everywhere until it is restored | D29: Access | E29: High | F29: Any | G29: Any time | I29: Signed in as SAO 990001. An archived organization with an administrator exists. | J29: 1. On the Archived tab read the buttons on the card. 2. Try to sign in as the organization administrator in another window. 3. Sign in as Department Head 940001 and look at the row on Organizations. 4. As SAO select Restore on the card and confirm Restore organization. 5. Read the green message and the Active tab. 6. Sign in as the organization administrator again. | K29: The card has only Open and Restore (no Review, Edit or Archive). The administrator cannot sign in and sees a clear message (VERIFY wording). The Department Head sees the row as Archived, Read only, with only View checklist. After restoring, "<Name> restored." appears, the organization is back on Active, and the administrator can sign in. | M29: Not run
A30: SAO-029 | B30: Organizations > Registrations and organizations | C30: On a phone the organization lists turn into cards and nothing is cut off | D30: Usability | E30: Medium | F30: Phone | G30: Any time | I30: Signed in as SAO 990001. Use a phone or a window narrower than 768 pixels. | J30: 1. Open Organizations > Agency overview. 2. Scroll to a college and read a row. 3. Open Registrations and organizations and open Review on a card. 4. Scroll the drawer to the bottom buttons. 5. Open Reviews > Compliance and read the Accreditation tab. | K30: Rows appear as readable cards, every button is large enough to tap, the Return and Approve buttons are reachable at the bottom of the drawer, and the page never scrolls sideways. | M30: Not run
A31: SAO-030 | B31: Organizations > Registrations and organizations > Open (Organization overview) | C31: The overview page shows one organization at a glance | D31: Functional | E31: High | F31: Laptop | G31: Any time | I31: Signed in as SAO 990001. Use PSITS-CCS. | J31: 1. Open Organizations > Agency overview and select Open on PSITS-CCS. 2. Read the heading, status and the registration steps. 3. Scroll through Leadership, Members by role, Events, Approved budgets, Compliance and Pending approvals. 4. Select Open the review queue, then go back. 5. Select Open on a document in Latest documents. 6. Select View all documents and then Back to agency overview. | K31: The page shows the name, "ACRONYM · College", a status badge and steps Registered, SAO review, Administrator, First use. Leadership lists people with positions and status. Members by role shows Students, SBO officers, Admins and Total. Events shows Upcoming and Recent ("None." when empty). Approved budgets shows Allocated, Spent, Income, Remaining and "N approved budgets. Only approved budgets are counted." Compliance shows the accreditation badge and Documents awaiting review. Pending approvals says how many requests wait. Open the review queue opens Compliance, Review queue tab; View all documents opens the Track documents tab; a document opens in a new tab; with none: "No documents have been submitted." | M31: Not run
A32: SAO-031 | B32: Organizations > Registrations and organizations > Open (Organization overview) | C32: An organization that does not exist shows an error with a way back | D32: Negative | E32: Low | F32: Any | G32: Any time | I32: Signed in as SAO 990001. | J32: 1. Replace the address end with /dashboard/super-admin/organizations/999999 and press Enter. 2. Read the message. 3. Select Back to agency overview. | K32: The page shows "Organization unavailable" with an error description and a Retry button. The link Back to agency overview returns to the Agency overview. | L32: VERIFY: description wording. | M32: Not run
A33: SAO-032 | B33: Organizations > Administrators | C33: The administrator list and its three summary tiles | D33: Functional | E33: High | F33: Any | G33: Any time | I33: Signed in as SAO 990001. | J33: 1. Open Organizations > Administrators. 2. Read the three tiles: Total Admins, Active Accounts, Organizations Covered. 3. Read the table columns and one row. 4. Look for the grey group headings between rows. 5. Find School IDs 900001, 920011, 990002 and 990032 in the table. | K33: Tiles show counts. The table columns are Administrator (name, then "email · School ID"), Organization (the code), Position ("Organization Admin" when none is set), Status and Action (a menu). Group headings read "Main organizations" and "Sub organizations". The seeded Admins and Advisers appear as active. | M33: Not run
A34: SAO-033 | B34: Organizations > Administrators | C34: Search and filter the administrator list | D34: Functional | E34: Medium | F34: Any | G34: Any time | I34: Signed in as SAO 990001. | J34: 1. Type 920011 in the search box (placeholder "Search name, School ID, email, or position"). 2. Clear it. Choose one organization in "Filter by organization". 3. Set "Filter by account status" to Inactive. 4. Read the result. 5. Set the status back to All statuses and choose All organizations. | K34: Each filter narrows the table. When nothing matches the table is replaced by "No administrator accounts match this view." with "Change the filters or create a new Admin user." Clearing the filters brings the rows back. Status options are All statuses, Active, Inactive and Disabled. | M34: Not run
A35: SAO-034 | B35: Organizations > Administrators | C35: Create an administrator who must change the password at first sign in | D35: Functional | E35: High | F35: Laptop | G35: Any time | I35: Signed in as SAO 990001. An Active organization exists (for example one just approved). | J35: 1. Select New Admin User. 2. Fill School ID (an unused number up to 8 digits, for example 9100123), First name, Last name and a new Email address. 3. Optionally fill Contact number and Position title (for example President). 4. Choose the Assigned organization. 5. Type the same Password and Confirm password (8 or more characters). 6. Select Create Admin User. 7. Read the green message and find the new row. 8. Sign in as the new administrator. | K35: The dialog closes and the green message reads "New Admin user created with the password set by SAO." The new administrator appears with status active. A box says "Done: <name> can sign in" with the button Open organization. The new administrator signs in with that password and must choose a new one before anything else opens, then reaches the Admin dashboard. | M35: Not run
A36: SAO-035 | B36: Organizations > Administrators | C36: The create form refuses missing, mismatched and bad values | D36: Validation | E36: High | F36: Any | G36: Any time | I36: Signed in as SAO 990001. | J36: 1. Select New Admin User and select Create Admin User with an empty form. 2. Fill every required field but type a different Confirm password. Select Create Admin User. 3. Make the passwords match but only 5 characters long and select Create Admin User. 4. Type abc (no @) in Email address and select Create Admin User. 5. Type 0 in School ID, then 100000000, and select Create Admin User each time. 6. Use an existing School ID such as 900001 and select Create Admin User. 7. Use a new School ID but an existing email and select Create Admin User. | K36: The browser stops an empty form and highlights the first empty field. Different passwords show the red message "Password confirmation does not match." A 5 character password, an email without @ and a School ID outside 1 to 99999999 are stopped by the browser. An existing School ID or email shows a red message such as "The school id has already been taken." or "The email has already been taken." (VERIFY wording). The dialog stays open and no account is created. | M36: Not run
A37: SAO-036 | B37: Organizations > Administrators | C37: Only active organizations can be chosen, and a provisioning link locks the choice | D37: Validation | E37: Medium | F37: Laptop | G37: Any time | I37: Signed in as SAO 990001. A Pending organization and an Active organization with no administrator exist. | J37: 1. Select New Admin User and open the Assigned organization list. 2. Check that Pending, Returned and Archived organizations are not listed. 3. Close the form. On Registrations and organizations select Provision administrator on the Active organization. 4. Check the Assigned organization field and the text under it. 5. Replace the address with /dashboard/super-admin/admins?organization=<id of the Pending organization>&create=1 and press Enter. 6. Read the red message. | K37: The list offers only active organizations as "ACRONYM: Name". With Provision administrator the field is greyed and says "Locked to the organization you are provisioning." For a pending organization the page says "<Name> is not active yet. Approve its registration before assigning an administrator." and no form opens. | M37: Not run
A38: SAO-037 | B38: Organizations > Administrators | C38: Edit an administrator | D38: Functional | E38: High | F38: Any | G38: Any time | I38: Signed in as SAO 990001. Use Admin 900002 or an administrator you created. | J38: 1. Open the Action menu of the row and choose Edit administrator. 2. Check that School ID cannot be changed and that there is no password field. 3. Change Position title. 4. Select Save Changes. 5. Read the green message and the row. | K38: The dialog is titled Edit Admin User and shows the School ID as plain text. There is no password field (the SAO cannot set an administrator password). After saving, "Administrator account updated successfully." appears and the Position column shows the new title. | M38: Not run
A39: SAO-038 | B39: Organizations > Administrators | C39: The last active administrator of an organization cannot be switched off | D39: Negative | E39: High | F39: Any | G39: Any time | I39: Signed in as SAO 990001. Organization NSC-CHS has only one Admin, Adviser 990032. | J39: 1. Find School ID 990032 and open Edit administrator. 2. Set Account status to Disabled. 3. Select Save Changes and read the red message. 4. Set Account status back to Active, then choose a different Assigned organization. 5. Select Save Changes and read the message again. | K39: Both attempts show the red message "Add another active administrator before transferring or deactivating this organization's last active administrator." The account stays active and in its organization. | M39: Not run
A40: SAO-039 | B40: Organizations > Administrators | C40: Send a password reset link to an administrator | D40: Functional | E40: Medium | F40: Any | G40: Any time | I40: Signed in as SAO 990001. Mail is switched off on the public copy, so no email arrives there. | J40: 1. Open the Action menu of an active administrator and choose Reset access. 2. Read the box titled Initiate password reset. 3. Select Send reset link. 4. Read the green message. 5. Open the Action menu of an inactive administrator and look at Reset access and Hand over role. | K40: The box says a secure reset link will be sent to the administrator's registered email and the current password is not shown. After Send reset link the green message reads "Password reset instructions were sent to the administrator email address." (VERIFY wording; on the public copy the mail is only written to the server log). For an inactive administrator Reset access and Hand over role are greyed out. | M40: Not run
...

Sheet Department Head
A1: ID | B1: Module | C1: Test case | D1: Type | E1: Priority | F1: Device | G1: Round | H1: Depends on | I1: Preconditions | J1: Steps | K1: Expected result | L1: Author note (unconfirmed) | M1: Status | N1: Severity | O1: Tester | P1: Date tested | Q1: Device and browser used | R1: Actual result / notes | S1: Bug screenshot link
A2: DH-001 | B2: Sign in | C2: Department Head signs in and lands on the Department Head dashboard | D2: Functional | E2: High | F2: Any | G2: Any time | I2: Account 940001 exists. The password is given to you separately. | J2: 1. Open the HIUSA address in a browser. 2. Type 940001 in School ID / ID Number. 3. Type the password you were given. 4. Select Sign in. | K2: You land on the Department Head Dashboard (the address ends with /dashboard/department-head). The top bar shows your name, your college and the label Department Head. The menu is the Department Head menu. | M2: Not run
A3: DH-002 | B3: Sign in | C3: Wrong password is refused with a clear message | D3: Negative | E3: High | F3: Any | G3: Any time | I3: Account 940001 exists. Use a different account than the one your teammates are using, because five wrong tries lock an account for 15 minutes. | J3: 1. Open the HIUSA address. 2. Type 940001 in School ID / ID Number. 3. Type a wrong password. 4. Select Sign in. | K3: You stay on the Sign in page. A message says: That school ID and password did not match. Check both and try again, or reset your password. No dashboard opens. | M3: Not run
A4: DH-003 | B4: Menu | C4: Sidebar shows exactly the Department Head menu | D4: Access | E4: High | F4: Any | G4: Any time | I4: Sign in as Department Head 940001 (College of Computer Studies, home of PSITS-CCS). The password is given to you separately. | J4: 1. Look at the left menu after sign in. 2. Read the top rows in order. 3. Find the heading College view (read only) and read what is under it. 4. Select Finance and read its sub items. 5. Look at the bottom of the menu. | K4: The menu reads: Dashboard, Approvals, Organizations. Under the heading College view (read only): Finance (Budgets, Ledger, Financial reports, Forecast), Calendar, Election results, Announcements. At the bottom: Profile and Study objectives. There is NO Members, Events and tasks, Voting, Store, Updates, Records or My activity group. Selecting Finance opens Budgets. | M4: Not run
A5: DH-004 | B5: Menu | C5: Phone: the menu opens from Open menu and every Department Head page can be reached | D5: Usability | E5: Medium | F5: Phone | G5: Any time | I5: Sign in as Department Head 940001 (College of Computer Studies, home of PSITS-CCS). The password is given to you separately. Use a phone or a browser window narrower than 1024 pixels. | J5: 1. Look at the top left of the screen. 2. Tap Open menu. 3. Tap Organizations. 4. Tap Open menu again and tap Approvals. 5. Tap Open menu again and tap Close menu. | K5: The menu slides in as a drawer. Each tap opens the right page and the drawer closes. Close menu hides the drawer. Nothing is cut off at the sides and no page scrolls sideways. | M5: Not run
A6: DH-005 | B6: Account menu | C6: Top bar shows who you are and the account menu has only your profile and Logout | D6: Usability | E6: Medium | F6: Any | G6: Any time | I6: Sign in as Department Head 940001 (College of Computer Studies, home of PSITS-CCS). The password is given to you separately. | J6: 1. Look at the top right of the screen. 2. Read your name, your college name and the label Department Head. 3. Select the account button (its name starts with Account menu for). 4. Read the Profiles section. 5. Look at the buttons under it. | K6: Your name, college and Department Head are shown. The Profiles section lists one profile with the word Current and says: This is your only active profile. Other profiles appear here when an organization adds you. The buttons are View Profile and Logout. | L6: VERIFY: the exact college text shown in the top bar (it comes from the college home organization). | M6: Not run
A7: DH-006 | B7: Account menu | C7: Logout asks first, then returns to Sign in | D7: Functional | E7: Medium | F7: Any | G7: Any time | I7: Sign in as Department Head 940001 (College of Computer Studies, home of PSITS-CCS). The password is given to you separately. | J7: 1. Select the account button in the top bar. 2. Select Logout. 3. Read the question that appears. 4. Confirm the logout. 5. Press the browser Back button. | K7: A confirmation appears before you are signed out. After you confirm, the Sign in page shows. Back should not show private pages again; you are asked to sign in. | L7: VERIFY: the exact words on the confirmation and what Back shows. | M7: Not run
A8: DH-007 | B8: Dashboard | C8: Dashboard shows the college, the approvals and the oversight snapshot | D8: Functional | E8: High | F8: Any | G8: Any time | I8: Sign in as Department Head 940001 (College of Computer Studies, home of PSITS-CCS). The password is given to you separately. | J8: 1. Select Dashboard in the menu. 2. Read the greeting at the top. 3. Find the box titled College of Computer Studies organizations. 4. Find the box titled Oversight snapshot. 5. Scroll down to Upcoming Events, Pending Approvals by Type and Recent Announcements. | K8: The page loads without an error. The college box says: Every student organization you oversee, by registration status. The Oversight snapshot has four tiles: Active Elections, Closed Elections, Upcoming Events, Pending Approvals. The lower boxes are Upcoming Events, Pending Approvals by Type and Recent Announcements. A box with nothing in it shows a short plain message, not a blank gap. | M8: Not run
A9: DH-008 | B9: Dashboard | C9: Organization status tiles show counts and open the matching list | D9: Functional | E9: High | F9: Any | G9: Any time | I9: Sign in as Department Head 940001 (College of Computer Studies, home of PSITS-CCS). The password is given to you separately. PSITS-CCS is Active. Register one more organization (see the Organizations cases) so there is also a Pending review row. | J9: 1. Open Dashboard. 2. In the college box read the four tiles: Returned, Pending review, Active, Archived. 3. Select the Pending review tile. 4. Look at the address and the tab that is selected. 5. Go back to Dashboard and select Manage organizations. | K9: Each tile shows a number that matches the rows in Organizations. The Pending review tile opens Organizations with the Pending review tab selected (the address ends with ?status=pending). Manage organizations opens Organizations with All selected. A Returned tile with a number above 0 is red and says Action needed. | M9: Not run
A10: DH-009 | B10: Dashboard | C10: Approvals banner counts the items waiting for the head and opens Approvals | D10: Functional | E10: High | F10: Any | G10: Any time | I10: A semester is active. Admin 900001 (PSITS-CCS) has proposed an event with dates inside the semester, so it waits for the Department Head. | J10: 1. Open Dashboard. 2. Find the yellow banner that says N item awaiting your approval. 3. Compare N with the Pending Approvals tile in Oversight snapshot. 4. Select the banner. | K10: The banner reads, for example, 1 item awaiting your approval (or items for more than one), with the line: Events, elections, and first-stage financial reports need your sign-off. The number matches the Pending Approvals tile. Selecting the banner opens Approvals. When nothing is pending the banner is not shown. | M10: Not run
A11: DH-010 | B11: Dashboard | C11: Election card and Upcoming Events box, including the empty messages | D11: Functional | E11: Medium | F11: Any | G11: Any time | I11: Sign in as Department Head 940001 (College of Computer Studies, home of PSITS-CCS). The password is given to you separately. | J11: 1. Open Dashboard. 2. Find the election card. It says either Active Election or No Active Election. 3. If an election is active, select View Results. 4. Go back to Dashboard and read the Upcoming Events box. 5. Select View all in the Upcoming Events box. | K11: With no running election the card says No Active Election and: No elections are currently running. With one running it shows the title, dates, a LIVE tag, View Details and View Results (View Results opens Election results). Upcoming Events lists up to four events with date, place and status, or says No upcoming events. View all opens the events list of your college. | M11: Not run
A12: DH-011 | B12: Dashboard | C12: Pending Approvals by Type and Recent Announcements boxes | D12: Functional | E12: Medium | F12: Any | G12: Any time | I12: A semester is active. Admin 900001 (PSITS-CCS) has proposed an event with dates inside the semester, so it waits for the Department Head. | J12: 1. Open Dashboard. 2. Find the box Pending Approvals by Type. 3. Select one request listed in it. 4. Go back to Dashboard and find the box Recent Announcements. 5. Select View all in that box. | K12: Pending Approvals by Type lists up to three waiting requests and a bar per type with a count and a percent. Selecting a request opens Approvals. With nothing waiting it says: Nothing awaiting your review. Recent Announcements shows up to three published announcements, or No announcements yet. View all opens Announcements. | M12: Not run
